Workbook

Sheet モデル
A1: ビンの寸法を選ぶ（SA-01、寸法候補8種類）― Excelソルバー版
A3: 採用する種類数 K | E3: 3
A4: 必要面積［目的セル・最小化］ | E4: =SUMPRODUCT('計算用'!E9:L25,E29:L45)
A5: ビン1個の面積（ブロック） | E5: 1 | F5: 2 | G5: 4 | H5: 3 | I5: 6 | J5: 8 | K5: 12 | L5: 16
A7: ① 必要なビンの数 n（前計算。空欄＝入らない）
A8: 部品番号 | B8: 部品名 | C8: 寸法(mm) | D8: 数量 | E8: 75x75 | F8: 150x75 | G8: 150x150 | H8: 225x75 | I8: 225x150 | J8: 300x150 | K8: 300x225 | L8: 300x300
A9: P-58407 | B9: ナット | C9: 20×22 | D9: 14 | E9: 1 | F9: 1 | G9: 1 | H9: 1 | I9: 1 | J9: 1 | K9: 1 | L9: 1
A10: P-81053 | B10: センサ | C10: 34×75 | D10: 2 | F10: 2 | G10: 1 | H10: 1 | I10: 1 | J10: 1 | K10: 1 | L10: 1
A11: P-84289 | B11: スペーサ | C11: 21×21 | D11: 23 | E11: 1 | F11: 1 | G11: 1 | H11: 1 | I11: 1 | J11: 1 | K11: 1 | L11: 1
A12: P-63881 | B12: センサ | C12: 36×88 | D12: 1 | F12: 1 | G12: 1 | H12: 1 | I12: 1 | J12: 1 | K12: 1 | L12: 1
A13: P-44602 | B13: ねじ | C13: 8×37 | D13: 22 | E13: 1 | F13: 1 | G13: 1 | H13: 1 | I13: 1 | J13: 1 | K13: 1 | L13: 1
A14: P-79847 | B14: ワッシャ | C14: 22×22 | D14: 4 | E14: 1 | F14: 1 | G14: 1 | H14: 1 | I14: 1 | J14: 1 | K14: 1 | L14: 1
A15: P-61411 | B15: ブラケット | C15: 27×50 | D15: 4 | E15: 2 | F15: 1 | G15: 1 | H15: 1 | I15: 1 | J15: 1 | K15: 1 | L15: 1
A16: P-19835 | B16: 継手 | C16: 23×85 | D16: 3 | F16: 2 | G16: 1 | H16: 1 | I16: 1 | J16: 1 | K16: 1 | L16: 1
A17: P-11058 | B17: バルブ | C17: 87×157 | D17: 2 | I17: 2 | J17: 2 | K17: 1 | L17: 1
A18: P-36550 | B18: ユニット | C18: 95×120 | D18: 1 | G18: 1 | I18: 1 | J18: 1 | K18: 1 | L18: 1
A19: P-57509 | B19: ボルト | C19: 12×12 | D19: 17 | E19: 1 | F19: 1 | G19: 1 | H19: 1 | I19: 1 | J19: 1 | K19: 1 | L19: 1
A20: P-55392 | B20: スペーサ | C20: 15×19 | D20: 22 | E20: 1 | F20: 1 | G20: 1 | H20: 1 | I20: 1 | J20: 1 | K20: 1 | L20: 1
A21: P-72339 | B21: フレーム | C21: 172×236 | D21: 1 | K21: 1 | L21: 1
A22: P-95547 | B22: スペーサ | C22: 23×23 | D22: 20 | E22: 1 | F22: 1 | G22: 1 | H22: 1 | I22: 1 | J22: 1 | K22: 1 | L22: 1
A23: P-93576 | B23: 継手 | C23: 35×84 | D23: 2 | F23: 2 | G23: 1 | H23: 1 | I23: 1 | J23: 1 | K23: 1 | L23: 1
A24: P-36241 | B24: センサ | C24: 38×44 | D24: 3 | E24: 3 | F24: 1 | G24: 1 | H24: 1 | I24: 1 | J24: 1 | K24: 1 | L24: 1
A25: P-23528 | B25: ワッシャ | C25: 19×22 | D25: 9 | E25: 1 | F25: 1 | G25: 1 | H25: 1 | I25: 1 | J25: 1 | K25: 1 | L25: 1
A27: ② x：部品をその寸法のビンに入れるか（0/1、変数セル）
A28: 部品番号 | B28: 部品名 | C28: 寸法(mm) | D28: 数量 | E28: 75x75 | F28: 150x75 | G28: 150x150 | H28: 225x75 | I28: 225x150 | J28: 300x150 | K28: 300x225 | L28: 300x300 | M28: 合計＝1
A29: P-58407 | B29: ナット | C29: 20×22 | D29: 14 | E29: 0 | F29: 0 | G29: 0 | H29: 0 | I29: 0 | J29: 0 | K29: 0 | L29: 0 | M29: =SUM(E29:L29)
A30: P-81053 | B30: センサ | C30: 34×75 | D30: 2 | E30: 0 | F30: 0 | G30: 0 | H30: 0 | I30: 0 | J30: 0 | K30: 0 | L30: 0 | M30: =SUM(E30:L30)
A31: P-84289 | B31: スペーサ | C31: 21×21 | D31: 23 | E31: 0 | F31: 0 | G31: 0 | H31: 0 | I31: 0 | J31: 0 | K31: 0 | L31: 0 | M31: =SUM(E31:L31)
A32: P-63881 | B32: センサ | C32: 36×88 | D32: 1 | E32: 0 | F32: 0 | G32: 0 | H32: 0 | I32: 0 | J32: 0 | K32: 0 | L32: 0 | M32: =SUM(E32:L32)
A33: P-44602 | B33: ねじ | C33: 8×37 | D33: 22 | E33: 0 | F33: 0 | G33: 0 | H33: 0 | I33: 0 | J33: 0 | K33: 0 | L33: 0 | M33: =SUM(E33:L33)
A34: P-79847 | B34: ワッシャ | C34: 22×22 | D34: 4 | E34: 0 | F34: 0 | G34: 0 | H34: 0 | I34: 0 | J34: 0 | K34: 0 | L34: 0 | M34: =SUM(E34:L34)
A35: P-61411 | B35: ブラケット | C35: 27×50 | D35: 4 | E35: 0 | F35: 0 | G35: 0 | H35: 0 | I35: 0 | J35: 0 | K35: 0 | L35: 0 | M35: =SUM(E35:L35)
A36: P-19835 | B36: 継手 | C36: 23×85 | D36: 3 | E36: 0 | F36: 0 | G36: 0 | H36: 0 | I36: 0 | J36: 0 | K36: 0 | L36: 0 | M36: =SUM(E36:L36)
A37: P-11058 | B37: バルブ | C37: 87×157 | D37: 2 | E37: 0 | F37: 0 | G37: 0 | H37: 0 | I37: 0 | J37: 0 | K37: 0 | L37: 0 | M37: =SUM(E37:L37)
A38: P-36550 | B38: ユニット | C38: 95×120 | D38: 1 | E38: 0 | F38: 0 | G38: 0 | H38: 0 | I38: 0 | J38: 0 | K38: 0 | L38: 0 | M38: =SUM(E38:L38)
A39: P-57509 | B39: ボルト | C39: 12×12 | D39: 17 | E39: 0 | F39: 0 | G39: 0 | H39: 0 | I39: 0 | J39: 0 | K39: 0 | L39: 0 | M39: =SUM(E39:L39)
A40: P-55392 | B40: スペーサ | C40: 15×19 | D40: 22 | E40: 0 | F40: 0 | G40: 0 | H40: 0 | I40: 0 | J40: 0 | K40: 0 | L40: 0 | M40: =SUM(E40:L40)
... A45: P-23528 | B45: ワッシャ | C45: 19×22 | D45: 9 | E45: 0 | F45: 0 | G45: 0 | H45: 0 | I45: 0 | J45: 0 | K45: 0 | L45: 0 | M45: =SUM(E45:L45)
A47: ③ y：その寸法を採用するか（0/1、変数セル） | E47: 0 | F47: 0 | G47: 0 | H47: 0 | I47: 0 | J47: 0 | K47: 0 | L47: 0 | M47: =SUM(E47:L47) | N47: ≦ K
A48: その寸法に入れた部品の数 | E48: =SUM(E29:E45) | F48: =SUM(F29:F45) | G48: =SUM(G29:G45) | H48: =SUM(H29:H45) | I48: =SUM(I29:I45) | J48: =SUM(J29:J45) | K48: =SUM(K29:K45) | L48: =SUM(L29:L45)
...

Sheet 計算用
E9: =IF(ISBLANK('モデル'!E9),1000,'モデル'!E$5*'モデル'!E9) | F9: =IF(ISBLANK('モデル'!F9),1000,'モデル'!F$5*'モデル'!F9) | G9: =IF(ISBLANK('モデル'!G9),1000,'モデル'!G$5*'モデル'!G9) | H9: =IF(ISBLANK('モデル'!H9),1000,'モデル'!H$5*'モデル'!H9) | I9: =IF(ISBLANK('モデル'!I9),1000,'モデル'!I$5*'モデル'!I9) | J9: =IF(ISBLANK('モデル'!J9),1000,'モデル'!J$5*'モデル'!J9) | K9: =IF(ISBLANK('モデル'!K9),1000,'モデル'!K$5*'モデル'!K9) | L9: =IF(ISBLANK('モデル'!L9),1000,'モデル'!L$5*'モデル'!L9)
E10: =IF(ISBLANK('モデル'!E10),1000,'モデル'!E$5*'モデル'!E10) | F10: =IF(ISBLANK('モデル'!F10),1000,'モデル'!F$5*'モデル'!F10) | G10: =IF(ISBLANK('モデル'!G10),1000,'モデル'!G$5*'モデル'!G10) | H10: =IF(ISBLANK('モデル'!H10),1000,'モデル'!H$5*'モデル'!H10) | I10: =IF(ISBLANK('モデル'!I10),1000,'モデル'!I$5*'モデル'!I10) | J10: =IF(ISBLANK('モデル'!J10),1000,'モデル'!J$5*'モデル'!J10) | K10: =IF(ISBLANK('モデル'!K10),1000,'モデル'!K$5*'モデル'!K10) | L10: =IF(ISBLANK('モデル'!L10),1000,'モデル'!L$5*'モデル'!L10)
E11: =IF(ISBLANK('モデル'!E11),1000,'モデル'!E$5*'モデル'!E11) | F11: =IF(ISBLANK('モデル'!F11),1000,'モデル'!F$5*'モデル'!F11) | G11: =IF(ISBLANK('モデル'!G11),1000,'モデル'!G$5*'モデル'!G11) | H11: =IF(ISBLANK('モデル'!H11),1000,'モデル'!H$5*'モデル'!H11) | I11: =IF(ISBLANK('モデル'!I11),1000,'モデル'!I$5*'モデル'!I11) | J11: =IF(ISBLANK('モデル'!J11),1000,'モデル'!J$5*'モデル'!J11) | K11: =IF(ISBLANK('モデル'!K11),1000,'モデル'!K$5*'モデル'!K11) | L11: =IF(ISBLANK('モデル'!L11),1000,'モデル'!L$5*'モデル'!L11)
E12: =IF(ISBLANK('モデル'!E12),1000,'モデル'!E$5*'モデル'!E12) | F12: =IF(ISBLANK('モデル'!F12),1000,'モデル'!F$5*'モデル'!F12) | G12: =IF(ISBLANK('モデル'!G12),1000,'モデル'!G$5*'モデル'!G12) | H12: =IF(ISBLANK('モデル'!H12),1000,'モデル'!H$5*'モデル'!H12) | I12: =IF(ISBLANK('モデル'!I12),1000,'モデル'!I$5*'モデル'!I12) | J12: =IF(ISBLANK('モデル'!J12),1000,'モデル'!J$5*'モデル'!J12) | K12: =IF(ISBLANK('モデル'!K12),1000,'モデル'!K$5*'モデル'!K12) | L12: =IF(ISBLANK('モデル'!L12),1000,'モデル'!L$5*'モデル'!L12)
E13: =IF(ISBLANK('モデル'!E13),1000,'モデル'!E$5*'モデル'!E13) | F13: =IF(ISBLANK('モデル'!F13),1000,'モデル'!F$5*'モデル'!F13) | G13: =IF(ISBLANK('モデル'!G13),1000,'モデル'!G$5*'モデル'!G13) | H13: =IF(ISBLANK('モデル'!H13),1000,'モデル'!H$5*'モデル'!H13) | I13: =IF(ISBLANK('モデル'!I13),1000,'モデル'!I$5*'モデル'!I13) | J13: =IF(ISBLANK('モデル'!J13),1000,'モデル'!J$5*'モデル'!J13) | K13: =IF(ISBLANK('モデル'!K13),1000,'モデル'!K$5*'モデル'!K13) | L13: =IF(ISBLANK('モデル'!L13),1000,'モデル'!L$5*'モデル'!L13)
E14: =IF(ISBLANK('モデル'!E14),1000,'モデル'!E$5*'モデル'!E14) | F14: =IF(ISBLANK('モデル'!F14),1000,'モデル'!F$5*'モデル'!F14) | G14: =IF(ISBLANK('モデル'!G14),1000,'モデル'!G$5*'モデル'!G14) | H14: =IF(ISBLANK('モデル'!H14),1000,'モデル'!H$5*'モデル'!H14) | I14: =IF(ISBLANK('モデル'!I14),1000,'モデル'!I$5*'モデル'!I14) | J14: =IF(ISBLANK('モデル'!J14),1000,'モデル'!J$5*'モデル'!J14) | K14: =IF(ISBLANK('モデル'!K14),1000,'モデル'!K$5*'モデル'!K14) | L14: =IF(ISBLANK('モデル'!L14),1000,'モデル'!L$5*'モデル'!L14)
E15: =IF(ISBLANK('モデル'!E15),1000,'モデル'!E$5*'モデル'!E15) | F15: =IF(ISBLANK('モデル'!F15),1000,'モデル'!F$5*'モデル'!F15) | G15: =IF(ISBLANK('モデル'!G15),1000,'モデル'!G$5*'モデル'!G15) | H15: =IF(ISBLANK('モデル'!H15),1000,'モデル'!H$5*'モデル'!H15) | I15: =IF(ISBLANK('モデル'!I15),1000,'モデル'!I$5*'モデル'!I15) | J15: =IF(ISBLANK('モデル'!J15),1000,'モデル'!J$5*'モデル'!J15) | K15: =IF(ISBLANK('モデル'!K15),1000,'モデル'!K$5*'モデル'!K15) | L15: =IF(ISBLANK('モデル'!L15),1000,'モデル'!L$5*'モデル'!L15)
E16: =IF(ISBLANK('モデル'!E16),1000,'モデル'!E$5*'モデル'!E16) | F16: =IF(ISBLANK('モデル'!F16),1000,'モデル'!F$5*'モデル'!F16) | G16: =IF(ISBLANK('モデル'!G16),1000,'モデル'!G$5*'モデル'!G16) | H16: =IF(ISBLANK('モデル'!H16),1000,'モデル'!H$5*'モデル'!H16) | I16: =IF(ISBLANK('モデル'!I16),1000,'モデル'!I$5*'モデル'!I16) | J16: =IF(ISBLANK('モデル'!J16),1000,'モデル'!J$5*'モデル'!J16) | K16: =IF(ISBLANK('モデル'!K16),1000,'モデル'!K$5*'モデル'!K16) | L16: =IF(ISBLANK('モデル'!L16),1000,'モデル'!L$5*'モデル'!L16)
E17: =IF(ISBLANK('モデル'!E17),1000,'モデル'!E$5*'モデル'!E17) | F17: =IF(ISBLANK('モデル'!F17),1000,'モデル'!F$5*'モデル'!F17) | G17: =IF(ISBLANK('モデル'!G17),1000,'モデル'!G$5*'モデル'!G17) | H17: =IF(ISBLANK('モデル'!H17),1000,'モデル'!H$5*'モデル'!H17) | I17: =IF(ISBLANK('モデル'!I17),1000,'モデル'!I$5*'モデル'!I17) | J17: =IF(ISBLANK('モデル'!J17),1000,'モデル'!J$5*'モデル'!J17) | K17: =IF(ISBLANK('モデル'!K17),1000,'モデル'!K$5*'モデル'!K17) | L17: =IF(ISBLANK('モデル'!L17),1000,'モデル'!L$5*'モデル'!L17)
E18: =IF(ISBLANK('モデル'!E18),1000,'モデル'!E$5*'モデル'!E18) | F18: =IF(ISBLANK('モデル'!F18),1000,'モデル'!F$5*'モデル'!F18) | G18: =IF(ISBLANK('モデル'!G18),1000,'モデル'!G$5*'モデル'!G18) | H18: =IF(ISBLANK('モデル'!H18),1000,'モデル'!H$5*'モデル'!H18) | I18: =IF(ISBLANK('モデル'!I18),1000,'モデル'!I$5*'モデル'!I18) | J18: =IF(ISBLANK('モデル'!J18),1000,'モデル'!J$5*'モデル'!J18) | K18: =IF(ISBLANK('モデル'!K18),1000,'モデル'!K$5*'モデル'!K18) | L18: =IF(ISBLANK('モデル'!L18),1000,'モデル'!L$5*'モデル'!L18)
E19: =IF(ISBLANK('モデル'!E19),1000,'モデル'!E$5*'モデル'!E19) | F19: =IF(ISBLANK('モデル'!F19),1000,'モデル'!F$5*'モデル'!F19) | G19: =IF(ISBLANK('モデル'!G19),1000,'モデル'!G$5*'モデル'!G19) | H19: =IF(ISBLANK('モデル'!H19),1000,'モデル'!H$5*'モデル'!H19) | I19: =IF(ISBLANK('モデル'!I19),1000,'モデル'!I$5*'モデル'!I19) | J19: =IF(ISBLANK('モデル'!J19),1000,'モデル'!J$5*'モデル'!J19) | K19: =IF(ISBLANK('モデル'!K19),1000,'モデル'!K$5*'モデル'!K19) | L19: =IF(ISBLANK('モデル'!L19),1000,'モデル'!L$5*'モデル'!L19)
E20: =IF(ISBLANK('モデル'!E20),1000,'モデル'!E$5*'モデル'!E20) | F20: =IF(ISBLANK('モデル'!F20),1000,'モデル'!F$5*'モデル'!F20) | G20: =IF(ISBLANK('モデル'!G20),1000,'モデル'!G$5*'モデル'!G20) | H20: =IF(ISBLANK('モデル'!H20),1000,'モデル'!H$5*'モデル'!H20) | I20: =IF(ISBLANK('モデル'!I20),1000,'モデル'!I$5*'モデル'!I20) | J20: =IF(ISBLANK('モデル'!J20),1000,'モデル'!J$5*'モデル'!J20) | K20: =IF(ISBLANK('モデル'!K20),1000,'モデル'!K$5*'モデル'!K20) | L20: =IF(ISBLANK('モデル'!L20),1000,'モデル'!L$5*'モデル'!L20)
... E25: =IF(ISBLANK('モデル'!E25),1000,'モデル'!E$5*'モデル'!E25) | F25: =IF(ISBLANK('モデル'!F25),1000,'モデル'!F$5*'モデル'!F25) | G25: =IF(ISBLANK('モデル'!G25),1000,'モデル'!G$5*'モデル'!G25) | H25: =IF(ISBLANK('モデル'!H25),1000,'モデル'!H$5*'モデル'!H25) | I25: =IF(ISBLANK('モデル'!I25),1000,'モデル'!I$5*'モデル'!I25) | J25: =IF(ISBLANK('モデル'!J25),1000,'モデル'!J$5*'モデル'!J25) | K25: =IF(ISBLANK('モデル'!K25),1000,'モデル'!K$5*'モデル'!K25) | L25: =IF(ISBLANK('モデル'!L25),1000,'モデル'!L$5*'モデル'!L25)
